2022-04-21 04:57:03,132 INFO    MainThread:2307443 [internal.py:wandb_internal():92] W&B internal server running at pid: 2307443, started at: 2022-04-21 04:57:03.131459
2022-04-21 04:57:03,135 INFO    WriterThread:2307443 [datastore.py:open_for_write():77] open: output/query_baseline/wandb/run-20220421_045702-p8xi52tl/run-p8xi52tl.wandb
2022-04-21 04:57:03,140 DEBUG   SenderThread:2307443 [sender.py:send():235] send: header
2022-04-21 04:57:03,140 DEBUG   SenderThread:2307443 [sender.py:send():235] send: run
2022-04-21 04:57:32,115 DEBUG   HandlerThread:2307443 [handler.py:handle_request():141] handle_request: shutdown
2022-04-21 04:57:32,115 INFO    HandlerThread:2307443 [handler.py:finish():790] shutting down handler
2022-04-21 04:57:32,145 INFO    WriterThread:2307443 [datastore.py:close():281] close: output/query_baseline/wandb/run-20220421_045702-p8xi52tl/run-p8xi52tl.wandb
2022-04-21 04:57:35,112 ERROR   SenderThread:2307443 [retry.py:__call__():126] Retry attempt failed:
Traceback (most recent call last):
  File "/home2/gaobofei/anaconda3/lib/python3.8/site-packages/urllib3/connectionpool.py", line 670, in urlopen
    httplib_response = self._make_request(
  File "/home2/gaobofei/anaconda3/lib/python3.8/site-packages/urllib3/connectionpool.py", line 381, in _make_request
    self._validate_conn(conn)
  File "/home2/gaobofei/anaconda3/lib/python3.8/site-packages/urllib3/connectionpool.py", line 978, in _validate_conn
    conn.connect()
  File "/home2/gaobofei/anaconda3/lib/python3.8/site-packages/urllib3/connection.py", line 362, in connect
    self.sock = ssl_wrap_socket(
  File "/home2/gaobofei/anaconda3/lib/python3.8/site-packages/urllib3/util/ssl_.py", line 386, in ssl_wrap_socket
    return context.wrap_socket(sock, server_hostname=server_hostname)
  File "/home2/gaobofei/anaconda3/lib/python3.8/ssl.py", line 500, in wrap_socket
    return self.sslsocket_class._create(
  File "/home2/gaobofei/anaconda3/lib/python3.8/ssl.py", line 1040, in _create
    self.do_handshake()
  File "/home2/gaobofei/anaconda3/lib/python3.8/ssl.py", line 1309, in do_handshake
    self._sslobj.do_handshake()
ConnectionResetError: [Errno 104] Connection reset by peer

During handling of the above exception, another exception occurred:

Traceback (most recent call last):
  File "/home2/gaobofei/anaconda3/lib/python3.8/site-packages/requests/adapters.py", line 439, in send
    resp = conn.urlopen(
  File "/home2/gaobofei/anaconda3/lib/python3.8/site-packages/urllib3/connectionpool.py", line 726, in urlopen
    retries = retries.increment(
  File "/home2/gaobofei/anaconda3/lib/python3.8/site-packages/urllib3/util/retry.py", line 410, in increment
    raise six.reraise(type(error), error, _stacktrace)
  File "/home2/gaobofei/anaconda3/lib/python3.8/site-packages/urllib3/packages/six.py", line 734, in reraise
    raise value.with_traceback(tb)
  File "/home2/gaobofei/anaconda3/lib/python3.8/site-packages/urllib3/connectionpool.py", line 670, in urlopen
    httplib_response = self._make_request(
  File "/home2/gaobofei/anaconda3/lib/python3.8/site-packages/urllib3/connectionpool.py", line 381, in _make_request
    self._validate_conn(conn)
  File "/home2/gaobofei/anaconda3/lib/python3.8/site-packages/urllib3/connectionpool.py", line 978, in _validate_conn
    conn.connect()
  File "/home2/gaobofei/anaconda3/lib/python3.8/site-packages/urllib3/connection.py", line 362, in connect
    self.sock = ssl_wrap_socket(
  File "/home2/gaobofei/anaconda3/lib/python3.8/site-packages/urllib3/util/ssl_.py", line 386, in ssl_wrap_socket
    return context.wrap_socket(sock, server_hostname=server_hostname)
  File "/home2/gaobofei/anaconda3/lib/python3.8/ssl.py", line 500, in wrap_socket
    return self.sslsocket_class._create(
  File "/home2/gaobofei/anaconda3/lib/python3.8/ssl.py", line 1040, in _create
    self.do_handshake()
  File "/home2/gaobofei/anaconda3/lib/python3.8/ssl.py", line 1309, in do_handshake
    self._sslobj.do_handshake()
urllib3.exceptions.ProtocolError: ('Connection aborted.', ConnectionResetError(104, 'Connection reset by peer'))

During handling of the above exception, another exception occurred:

Traceback (most recent call last):
  File "/home2/gaobofei/anaconda3/lib/python3.8/site-packages/wandb/sdk/lib/retry.py", line 102, in __call__
    result = self._call_fn(*args, **kwargs)
  File "/home2/gaobofei/anaconda3/lib/python3.8/site-packages/wandb/sdk/internal/internal_api.py", line 141, in execute
    return self.client.execute(*args, **kwargs)
  File "/home2/gaobofei/anaconda3/lib/python3.8/site-packages/wandb/vendor/gql-0.2.0/wandb_gql/client.py", line 52, in execute
    result = self._get_result(document, *args, **kwargs)
  File "/home2/gaobofei/anaconda3/lib/python3.8/site-packages/wandb/vendor/gql-0.2.0/wandb_gql/client.py", line 60, in _get_result
    return self.transport.execute(document, *args, **kwargs)
  File "/home2/gaobofei/anaconda3/lib/python3.8/site-packages/wandb/vendor/gql-0.2.0/wandb_gql/transport/requests.py", line 38, in execute
    request = requests.post(self.url, **post_args)
  File "/home2/gaobofei/anaconda3/lib/python3.8/site-packages/requests/api.py", line 119, in post
    return request('post', url, data=data, json=json, **kwargs)
  File "/home2/gaobofei/anaconda3/lib/python3.8/site-packages/requests/api.py", line 61, in request
    return session.request(method=method, url=url, **kwargs)
  File "/home2/gaobofei/anaconda3/lib/python3.8/site-packages/requests/sessions.py", line 530, in request
    resp = self.send(prep, **send_kwargs)
  File "/home2/gaobofei/anaconda3/lib/python3.8/site-packages/requests/sessions.py", line 643, in send
    r = adapter.send(request, **kwargs)
  File "/home2/gaobofei/anaconda3/lib/python3.8/site-packages/requests/adapters.py", line 498, in send
    raise ConnectionError(err, request=request)
requests.exceptions.ConnectionError: ('Connection aborted.', ConnectionResetError(104, 'Connection reset by peer'))
2022-04-21 04:57:58,106 INFO    SenderThread:2307443 [dir_watcher.py:__init__():169] watching files in: output/query_baseline/wandb/run-20220421_045702-p8xi52tl/files
2022-04-21 04:57:58,107 INFO    SenderThread:2307443 [sender.py:_start_run_threads():812] run started: p8xi52tl with start time 1650517022
2022-04-21 04:57:58,107 INFO    SenderThread:2307443 [sender.py:finish():1107] shutting down sender
2022-04-21 04:57:58,107 INFO    SenderThread:2307443 [dir_watcher.py:finish():283] shutting down directory watcher
2022-04-21 04:57:59,107 INFO    SenderThread:2307443 [dir_watcher.py:finish():313] scan: output/query_baseline/wandb/run-20220421_045702-p8xi52tl/files
2022-04-21 04:57:59,107 INFO    SenderThread:2307443 [dir_watcher.py:finish():327] scan save: output/query_baseline/wandb/run-20220421_045702-p8xi52tl/files/config.yaml config.yaml
2022-04-21 04:57:59,108 INFO    SenderThread:2307443 [file_pusher.py:finish():145] shutting down file pusher
2022-04-21 04:57:59,108 INFO    SenderThread:2307443 [file_pusher.py:join():150] waiting for file pusher
2022-04-21 04:58:11,188 INFO    Thread-9  :2307443 [upload_job.py:push():137] Uploaded file output/query_baseline/wandb/run-20220421_045702-p8xi52tl/files/config.yaml
2022-04-21 04:58:12,029 INFO    MainThread:2307443 [internal.py:handle_exit():82] Internal process exited
