2022-04-21 04:51:20,644 INFO    MainThread:2306009 [internal.py:wandb_internal():92] W&B internal server running at pid: 2306009, started at: 2022-04-21 04:51:20.644048
2022-04-21 04:51:20,649 DEBUG   SenderThread:2306009 [sender.py:send():235] send: header
2022-04-21 04:51:20,649 INFO    WriterThread:2306009 [datastore.py:open_for_write():77] open: output/query_baseline/wandb/run-20220421_045119-35p0bgvn/run-35p0bgvn.wandb
2022-04-21 04:51:20,650 DEBUG   SenderThread:2306009 [sender.py:send():235] send: run
2022-04-21 04:51:49,586 DEBUG   HandlerThread:2306009 [handler.py:handle_request():141] handle_request: shutdown
2022-04-21 04:51:49,586 INFO    HandlerThread:2306009 [handler.py:finish():790] shutting down handler
2022-04-21 04:51:49,656 INFO    WriterThread:2306009 [datastore.py:close():281] close: output/query_baseline/wandb/run-20220421_045119-35p0bgvn/run-35p0bgvn.wandb
2022-04-21 04:51:55,903 ERROR   SenderThread:2306009 [retry.py:__call__():126] Retry attempt failed:
Traceback (most recent call last):
  File "/home2/gaobofei/anaconda3/lib/python3.8/site-packages/urllib3/connection.py", line 159, in _new_conn
    conn = connection.create_connection(
  File "/home2/gaobofei/anaconda3/lib/python3.8/site-packages/urllib3/util/connection.py", line 84, in create_connection
    raise err
  File "/home2/gaobofei/anaconda3/lib/python3.8/site-packages/urllib3/util/connection.py", line 74, in create_connection
    sock.connect(sa)
socket.timeout: timed out

During handling of the above exception, another exception occurred:

Traceback (most recent call last):
  File "/home2/gaobofei/anaconda3/lib/python3.8/site-packages/urllib3/connectionpool.py", line 670, in urlopen
    httplib_response = self._make_request(
  File "/home2/gaobofei/anaconda3/lib/python3.8/site-packages/urllib3/connectionpool.py", line 381, in _make_request
    self._validate_conn(conn)
  File "/home2/gaobofei/anaconda3/lib/python3.8/site-packages/urllib3/connectionpool.py", line 978, in _validate_conn
    conn.connect()
  File "/home2/gaobofei/anaconda3/lib/python3.8/site-packages/urllib3/connection.py", line 309, in connect
    conn = self._new_conn()
  File "/home2/gaobofei/anaconda3/lib/python3.8/site-packages/urllib3/connection.py", line 164, in _new_conn
    raise ConnectTimeoutError(
urllib3.exceptions.ConnectTimeoutError: (<urllib3.connection.HTTPSConnection object at 0x7fbe7999b250>, 'Connection to api.wandb.ai timed out. (connect timeout=10)')

During handling of the above exception, another exception occurred:

Traceback (most recent call last):
  File "/home2/gaobofei/anaconda3/lib/python3.8/site-packages/requests/adapters.py", line 439, in send
    resp = conn.urlopen(
  File "/home2/gaobofei/anaconda3/lib/python3.8/site-packages/urllib3/connectionpool.py", line 726, in urlopen
    retries = retries.increment(
  File "/home2/gaobofei/anaconda3/lib/python3.8/site-packages/urllib3/util/retry.py", line 446, in increment
    raise MaxRetryError(_pool, url, error or ResponseError(cause))
urllib3.exceptions.MaxRetryError: HTTPSConnectionPool(host='api.wandb.ai', port=443): Max retries exceeded with url: /graphql (Caused by ConnectTimeoutError(<urllib3.connection.HTTPSConnection object at 0x7fbe7999b250>, 'Connection to api.wandb.ai timed out. (connect timeout=10)'))

During handling of the above exception, another exception occurred:

Traceback (most recent call last):
  File "/home2/gaobofei/anaconda3/lib/python3.8/site-packages/wandb/sdk/lib/retry.py", line 102, in __call__
    result = self._call_fn(*args, **kwargs)
  File "/home2/gaobofei/anaconda3/lib/python3.8/site-packages/wandb/sdk/internal/internal_api.py", line 141, in execute
    return self.client.execute(*args, **kwargs)
  File "/home2/gaobofei/anaconda3/lib/python3.8/site-packages/wandb/vendor/gql-0.2.0/wandb_gql/client.py", line 52, in execute
    result = self._get_result(document, *args, **kwargs)
  File "/home2/gaobofei/anaconda3/lib/python3.8/site-packages/wandb/vendor/gql-0.2.0/wandb_gql/client.py", line 60, in _get_result
    return self.transport.execute(document, *args, **kwargs)
  File "/home2/gaobofei/anaconda3/lib/python3.8/site-packages/wandb/vendor/gql-0.2.0/wandb_gql/transport/requests.py", line 38, in execute
    request = requests.post(self.url, **post_args)
  File "/home2/gaobofei/anaconda3/lib/python3.8/site-packages/requests/api.py", line 119, in post
    return request('post', url, data=data, json=json, **kwargs)
  File "/home2/gaobofei/anaconda3/lib/python3.8/site-packages/requests/api.py", line 61, in request
    return session.request(method=method, url=url, **kwargs)
  File "/home2/gaobofei/anaconda3/lib/python3.8/site-packages/requests/sessions.py", line 530, in request
    resp = self.send(prep, **send_kwargs)
  File "/home2/gaobofei/anaconda3/lib/python3.8/site-packages/requests/sessions.py", line 643, in send
    r = adapter.send(request, **kwargs)
  File "/home2/gaobofei/anaconda3/lib/python3.8/site-packages/requests/adapters.py", line 504, in send
    raise ConnectTimeout(e, request=request)
requests.exceptions.ConnectTimeout: HTTPSConnectionPool(host='api.wandb.ai', port=443): Max retries exceeded with url: /graphql (Caused by ConnectTimeoutError(<urllib3.connection.HTTPSConnection object at 0x7fbe7999b250>, 'Connection to api.wandb.ai timed out. (connect timeout=10)'))
2022-04-21 04:52:25,956 ERROR   SenderThread:2306009 [internal_api.py:execute():144] 404 response executing GraphQL.
2022-04-21 04:52:25,957 ERROR   SenderThread:2306009 [internal_api.py:execute():145] {"errors":[{"message":"entity RUC-BUPT not found during upsertBucket","path":["upsertBucket"]}],"data":{"upsertBucket":null}}
2022-04-21 04:52:25,957 ERROR   MainThread:2306009 [internal.py:wandb_internal():167] Thread SenderThread:
Traceback (most recent call last):
  File "/home2/gaobofei/anaconda3/lib/python3.8/site-packages/wandb/sdk/lib/retry.py", line 102, in __call__
    result = self._call_fn(*args, **kwargs)
  File "/home2/gaobofei/anaconda3/lib/python3.8/site-packages/wandb/sdk/internal/internal_api.py", line 147, in execute
    six.reraise(*sys.exc_info())
  File "/home2/gaobofei/anaconda3/lib/python3.8/site-packages/six.py", line 703, in reraise
    raise value
  File "/home2/gaobofei/anaconda3/lib/python3.8/site-packages/wandb/sdk/internal/internal_api.py", line 141, in execute
    return self.client.execute(*args, **kwargs)
  File "/home2/gaobofei/anaconda3/lib/python3.8/site-packages/wandb/vendor/gql-0.2.0/wandb_gql/client.py", line 52, in execute
    result = self._get_result(document, *args, **kwargs)
  File "/home2/gaobofei/anaconda3/lib/python3.8/site-packages/wandb/vendor/gql-0.2.0/wandb_gql/client.py", line 60, in _get_result
    return self.transport.execute(document, *args, **kwargs)
  File "/home2/gaobofei/anaconda3/lib/python3.8/site-packages/wandb/vendor/gql-0.2.0/wandb_gql/transport/requests.py", line 39, in execute
    request.raise_for_status()
  File "/home2/gaobofei/anaconda3/lib/python3.8/site-packages/requests/models.py", line 941, in raise_for_status
    raise HTTPError(http_error_msg, response=self)
requests.exceptions.HTTPError: 404 Client Error: Not Found for url: https://api.wandb.ai/graphql

During handling of the above exception, another exception occurred:

Traceback (most recent call last):
  File "/home2/gaobofei/anaconda3/lib/python3.8/site-packages/wandb/apis/normalize.py", line 24, in wrapper
    return func(*args, **kwargs)
  File "/home2/gaobofei/anaconda3/lib/python3.8/site-packages/wandb/sdk/internal/internal_api.py", line 1315, in upsert_run
    response = self.gql(mutation, variable_values=variable_values, **kwargs)
  File "/home2/gaobofei/anaconda3/lib/python3.8/site-packages/wandb/sdk/lib/retry.py", line 118, in __call__
    if not check_retry_fn(e):
  File "/home2/gaobofei/anaconda3/lib/python3.8/site-packages/wandb/util.py", line 873, in no_retry_auth
    raise CommError("Permission denied, ask the project owner to grant you access")
wandb.errors.CommError: Permission denied, ask the project owner to grant you access

During handling of the above exception, another exception occurred:

Traceback (most recent call last):
  File "/home2/gaobofei/anaconda3/lib/python3.8/site-packages/wandb/sdk/internal/internal_util.py", line 54, in run
    self._run()
  File "/home2/gaobofei/anaconda3/lib/python3.8/site-packages/wandb/sdk/internal/internal_util.py", line 105, in _run
    self._process(record)
  File "/home2/gaobofei/anaconda3/lib/python3.8/site-packages/wandb/sdk/internal/internal.py", line 312, in _process
    self._sm.send(record)
  File "/home2/gaobofei/anaconda3/lib/python3.8/site-packages/wandb/sdk/internal/sender.py", line 237, in send
    send_handler(record)
  File "/home2/gaobofei/anaconda3/lib/python3.8/site-packages/wandb/sdk/internal/sender.py", line 695, in send_run
    self._init_run(run, config_value_dict)
  File "/home2/gaobofei/anaconda3/lib/python3.8/site-packages/wandb/sdk/internal/sender.py", line 719, in _init_run
    server_run, inserted = self._api.upsert_run(
  File "/home2/gaobofei/anaconda3/lib/python3.8/site-packages/wandb/apis/normalize.py", line 62, in wrapper
    six.reraise(CommError, CommError(message, err), sys.exc_info()[2])
  File "/home2/gaobofei/anaconda3/lib/python3.8/site-packages/six.py", line 702, in reraise
    raise value.with_traceback(tb)
  File "/home2/gaobofei/anaconda3/lib/python3.8/site-packages/wandb/apis/normalize.py", line 24, in wrapper
    return func(*args, **kwargs)
  File "/home2/gaobofei/anaconda3/lib/python3.8/site-packages/wandb/sdk/internal/internal_api.py", line 1315, in upsert_run
    response = self.gql(mutation, variable_values=variable_values, **kwargs)
  File "/home2/gaobofei/anaconda3/lib/python3.8/site-packages/wandb/sdk/lib/retry.py", line 118, in __call__
    if not check_retry_fn(e):
  File "/home2/gaobofei/anaconda3/lib/python3.8/site-packages/wandb/util.py", line 873, in no_retry_auth
    raise CommError("Permission denied, ask the project owner to grant you access")
wandb.errors.CommError: Permission denied, ask the project owner to grant you access
2022-04-21 04:52:27,984 INFO    MainThread:2306009 [internal.py:handle_exit():82] Internal process exited
