2022-04-21 04:51:19,484 INFO    MainThread:2305932 [wandb_setup.py:_flush():75] Loading settings from /home2/gaobofei/.config/wandb/settings
2022-04-21 04:51:19,484 INFO    MainThread:2305932 [wandb_setup.py:_flush():75] Loading settings from /home2/gaobofei/dialogue/CPT/finetune/dialogue_no_trainer/wandb/settings
2022-04-21 04:51:19,484 INFO    MainThread:2305932 [wandb_setup.py:_flush():75] Loading settings from environment variables: {}
2022-04-21 04:51:19,484 INFO    MainThread:2305932 [wandb_setup.py:_flush():75] Inferring run settings from compute environment: {'program_relpath': 'query_gen_notrainer.py', 'program': 'query_gen_notrainer.py'}
2022-04-21 04:51:19,484 INFO    MainThread:2305932 [wandb_init.py:_log_setup():438] Logging user logs to output/query_baseline/wandb/run-20220421_045119-21iuv8vz/logs/debug.log
2022-04-21 04:51:19,484 INFO    MainThread:2305932 [wandb_init.py:_log_setup():439] Logging internal logs to output/query_baseline/wandb/run-20220421_045119-21iuv8vz/logs/debug-internal.log
2022-04-21 04:51:19,484 INFO    MainThread:2305932 [wandb_init.py:init():472] calling init triggers
2022-04-21 04:51:19,485 INFO    MainThread:2305932 [wandb_init.py:init():475] wandb.init called with sweep_config: {}
config: {'model_path': 'fnlp/cpt-base', 'data_dir': 'data/DuSinc_dial', 'output_dir': 'output/query_baseline', 'train_file': 'DuSinc/dialogue/train.csv', 'validation_file': 'DuSinc/dialogue/dev.csv', 'test_file': 'DuSinc/dialogue/test.csv', 'max_source_length': 512, 'max_target_length': 256, 'mode': 'train', 'per_device_batch_size': 5, 'learning_rate': 1e-05, 'weight_decay': 0.0, 'num_train_epochs': 10, 'max_train_steps': None, 'gradient_accumulation_steps': 1, 'lr_scheduler_type': <SchedulerType.LINEAR: 'linear'>, 'num_warmup_steps': 0, 'seed': 42, 'num_beams': 4, 'checkpointing_steps': 'epoch', 'team_name': 'RUC-BUPT', 'project_name': 'Paddle SINC', 'experiment_name': 'query_gen', 'scenario_name': 'batch_size4*5,baseline_input'}
2022-04-21 04:51:19,485 INFO    MainThread:2305932 [wandb_init.py:init():525] starting backend
2022-04-21 04:51:19,485 INFO    MainThread:2305932 [backend.py:_multiprocessing_setup():99] multiprocessing start_methods=fork,spawn,forkserver, using: spawn
2022-04-21 04:51:19,520 INFO    MainThread:2305932 [backend.py:ensure_launched():219] starting backend process...
2022-04-21 04:51:19,538 INFO    MainThread:2305932 [backend.py:ensure_launched():224] started backend process with pid: 2306007
2022-04-21 04:51:19,540 INFO    MainThread:2305932 [wandb_init.py:init():534] backend started and connected
2022-04-21 04:51:19,552 INFO    MainThread:2305932 [wandb_init.py:init():598] updated telemetry
2022-04-21 04:51:19,573 INFO    MainThread:2305932 [wandb_init.py:init():629] communicating run to backend with 30 second timeout
2022-04-21 04:51:49,575 INFO    MainThread:2305932 [interface_shared.py:_communicate_run():325] couldn't get run from backend
2022-04-21 04:51:49,575 ERROR   MainThread:2305932 [wandb_init.py:init():634] backend process timed out
2022-04-21 04:51:49,576 ERROR   MainThread:2305932 [wandb_init.py:init():645] encountered error: Error communicating with wandb process
try: wandb.init(settings=wandb.Settings(start_method='fork'))
or:  wandb.init(settings=wandb.Settings(start_method='thread'))
For more info see: https://docs.wandb.ai/library/init#init-start-error
2022-04-21 04:51:50,266 ERROR   Thread-1  :2305932 [retry.py:__call__():126] Retry attempt failed:
Traceback (most recent call last):
  File "/home2/gaobofei/anaconda3/lib/python3.8/site-packages/urllib3/connection.py", line 159, in _new_conn
    conn = connection.create_connection(
  File "/home2/gaobofei/anaconda3/lib/python3.8/site-packages/urllib3/util/connection.py", line 84, in create_connection
    raise err
  File "/home2/gaobofei/anaconda3/lib/python3.8/site-packages/urllib3/util/connection.py", line 74, in create_connection
    sock.connect(sa)
socket.timeout: timed out

During handling of the above exception, another exception occurred:

Traceback (most recent call last):
  File "/home2/gaobofei/anaconda3/lib/python3.8/site-packages/urllib3/connectionpool.py", line 670, in urlopen
    httplib_response = self._make_request(
  File "/home2/gaobofei/anaconda3/lib/python3.8/site-packages/urllib3/connectionpool.py", line 381, in _make_request
    self._validate_conn(conn)
  File "/home2/gaobofei/anaconda3/lib/python3.8/site-packages/urllib3/connectionpool.py", line 978, in _validate_conn
    conn.connect()
  File "/home2/gaobofei/anaconda3/lib/python3.8/site-packages/urllib3/connection.py", line 309, in connect
    conn = self._new_conn()
  File "/home2/gaobofei/anaconda3/lib/python3.8/site-packages/urllib3/connection.py", line 164, in _new_conn
    raise ConnectTimeoutError(
urllib3.exceptions.ConnectTimeoutError: (<urllib3.connection.HTTPSConnection object at 0x7f0902ef4250>, 'Connection to api.wandb.ai timed out. (connect timeout=10)')

During handling of the above exception, another exception occurred:

Traceback (most recent call last):
  File "/home2/gaobofei/anaconda3/lib/python3.8/site-packages/requests/adapters.py", line 439, in send
    resp = conn.urlopen(
  File "/home2/gaobofei/anaconda3/lib/python3.8/site-packages/urllib3/connectionpool.py", line 726, in urlopen
    retries = retries.increment(
  File "/home2/gaobofei/anaconda3/lib/python3.8/site-packages/urllib3/util/retry.py", line 446, in increment
    raise MaxRetryError(_pool, url, error or ResponseError(cause))
urllib3.exceptions.MaxRetryError: HTTPSConnectionPool(host='api.wandb.ai', port=443): Max retries exceeded with url: /graphql (Caused by ConnectTimeoutError(<urllib3.connection.HTTPSConnection object at 0x7f0902ef4250>, 'Connection to api.wandb.ai timed out. (connect timeout=10)'))

During handling of the above exception, another exception occurred:

Traceback (most recent call last):
  File "/home2/gaobofei/anaconda3/lib/python3.8/site-packages/wandb/sdk/lib/retry.py", line 102, in __call__
    result = self._call_fn(*args, **kwargs)
  File "/home2/gaobofei/anaconda3/lib/python3.8/site-packages/wandb/sdk/internal/internal_api.py", line 141, in execute
    return self.client.execute(*args, **kwargs)
  File "/home2/gaobofei/anaconda3/lib/python3.8/site-packages/wandb/vendor/gql-0.2.0/wandb_gql/client.py", line 52, in execute
    result = self._get_result(document, *args, **kwargs)
  File "/home2/gaobofei/anaconda3/lib/python3.8/site-packages/wandb/vendor/gql-0.2.0/wandb_gql/client.py", line 60, in _get_result
    return self.transport.execute(document, *args, **kwargs)
  File "/home2/gaobofei/anaconda3/lib/python3.8/site-packages/wandb/vendor/gql-0.2.0/wandb_gql/transport/requests.py", line 38, in execute
    request = requests.post(self.url, **post_args)
  File "/home2/gaobofei/anaconda3/lib/python3.8/site-packages/requests/api.py", line 119, in post
    return request('post', url, data=data, json=json, **kwargs)
  File "/home2/gaobofei/anaconda3/lib/python3.8/site-packages/requests/api.py", line 61, in request
    return session.request(method=method, url=url, **kwargs)
  File "/home2/gaobofei/anaconda3/lib/python3.8/site-packages/requests/sessions.py", line 530, in request
    resp = self.send(prep, **send_kwargs)
  File "/home2/gaobofei/anaconda3/lib/python3.8/site-packages/requests/sessions.py", line 643, in send
    r = adapter.send(request, **kwargs)
  File "/home2/gaobofei/anaconda3/lib/python3.8/site-packages/requests/adapters.py", line 504, in send
    raise ConnectTimeout(e, request=request)
requests.exceptions.ConnectTimeout: HTTPSConnectionPool(host='api.wandb.ai', port=443): Max retries exceeded with url: /graphql (Caused by ConnectTimeoutError(<urllib3.connection.HTTPSConnection object at 0x7f0902ef4250>, 'Connection to api.wandb.ai timed out. (connect timeout=10)'))
